[2025-10-12 13:15:53,346] [ERROR] [common] {"type": "exception", "user": "allanlondon19452122@gmail.com", "method": "GET", "path": "/test-error/", "query_params": {}, "body": {}, "exception": "division by zero", "traceback": "Traceback (most recent call last):\n  File \"E:\\Python\\Lib\\site-packages\\django\\core\\handlers\\base.py\", line 197, in _get_response\n    response = wrapped_callback(request, *callback_args, **callback_kwargs)\n  File \"E:\\2VAKIL\\AloVakil\\common\\views.py\", line 5, in test_error\n    1 / 0\n    ~~^~~\nZeroDivisionError: division by zero\n"}
[2025-10-12 13:15:53,390] [ERROR] [django.request] Internal Server Error: /test-error/
Traceback (most recent call last):
  File "E:\Python\Lib\site-packages\django\core\handlers\exception.py", line 55, in inner
    response = get_response(request)
  File "E:\Python\Lib\site-packages\django\core\handlers\base.py", line 197, in _get_response
    response = wrapped_callback(request, *callback_args, **callback_kwargs)
  File "E:\2VAKIL\AloVakil\common\views.py", line 5, in test_error
    1 / 0
    ~~^~~
ZeroDivisionError: division by zero
[2025-10-12 13:15:53,392] [ERROR] [django.server] "GET /test-error/ HTTP/1.1" 500 76849
[2025-10-15 12:46:32,673] [ERROR] [common] {"type": "exception", "user": "allanlondon19452122@gmail.com", "method": "GET", "path": "/users/verify-email/", "query_params": {}, "body": {}, "exception": "'NoneType' object has no attribute 'encode'", "traceback": "Traceback (most recent call last):\n  File \"E:\\Python\\Lib\\site-packages\\django\\core\\handlers\\base.py\", line 197, in _get_response\n    response = wrapped_callback(request, *callback_args, **callback_kwargs)\n  File \"E:\\Python\\Lib\\site-packages\\django\\views\\decorators\\csrf.py\", line 65, in _view_wrapper\n    return view_func(request, *args, **kwargs)\n  File \"E:\\Python\\Lib\\site-packages\\django\\views\\generic\\base.py\", line 105, in view\n    return self.dispatch(request, *args, **kwargs)\n           ~~~~~~~~~~~~~^^^^^^^^^^^^^^^^^^^^^^^^^^\n  File \"E:\\Python\\Lib\\site-packages\\rest_framework\\views.py\", line 515, in dispatch\n    response = self.handle_exception(exc)\n  File \"E:\\Python\\Lib\\site-packages\\rest_framework\\views.py\", line 475, in handle_exception\n    self.raise_uncaught_exception(exc)\n    ~~~~~~~~~~~~~~~~~~~~~~~~~~~~~^^^^^\n  File \"E:\\Python\\Lib\\site-packages\\rest_framework\\views.py\", line 486, in raise_uncaught_exception\n    raise exc\n  File \"E:\\Python\\Lib\\site-packages\\rest_framework\\views.py\", line 512, in dispatch\n    response = handler(request, *args, **kwargs)\n  File \"E:\\2VAKIL\\AloVakil\\users\\views.py\", line 49, in get\n    uid = force_str(urlsafe_base64_decode(uidb64))\n                    ~~~~~~~~~~~~~~~~~~~~~^^^^^^^^\n  File \"E:\\Python\\Lib\\site-packages\\django\\utils\\http.py\", line 191, in urlsafe_base64_decode\n    s = s.encode()\n        ^^^^^^^^\nAttributeError: 'NoneType' object has no attribute 'encode'\n"}
[2025-10-15 12:46:32,722] [ERROR] [django.request] Internal Server Error: /users/verify-email/
Traceback (most recent call last):
  File "E:\Python\Lib\site-packages\django\core\handlers\exception.py", line 55, in inner
    response = get_response(request)
  File "E:\Python\Lib\site-packages\django\core\handlers\base.py", line 197, in _get_response
    response = wrapped_callback(request, *callback_args, **callback_kwargs)
  File "E:\Python\Lib\site-packages\django\views\decorators\csrf.py", line 65, in _view_wrapper
    return view_func(request, *args, **kwargs)
  File "E:\Python\Lib\site-packages\django\views\generic\base.py", line 105, in view
    return self.dispatch(request, *args, **kwargs)
           ~~~~~~~~~~~~~^^^^^^^^^^^^^^^^^^^^^^^^^^
  File "E:\Python\Lib\site-packages\rest_framework\views.py", line 515, in dispatch
    response = self.handle_exception(exc)
  File "E:\Python\Lib\site-packages\rest_framework\views.py", line 475, in handle_exception
    self.raise_uncaught_exception(exc)
    ~~~~~~~~~~~~~~~~~~~~~~~~~~~~~^^^^^
  File "E:\Python\Lib\site-packages\rest_framework\views.py", line 486, in raise_uncaught_exception
    raise exc
  File "E:\Python\Lib\site-packages\rest_framework\views.py", line 512, in dispatch
    response = handler(request, *args, **kwargs)
  File "E:\2VAKIL\AloVakil\users\views.py", line 49, in get
    uid = force_str(urlsafe_base64_decode(uidb64))
                    ~~~~~~~~~~~~~~~~~~~~~^^^^^^^^
  File "E:\Python\Lib\site-packages\django\utils\http.py", line 191, in urlsafe_base64_decode
    s = s.encode()
        ^^^^^^^^
AttributeError: 'NoneType' object has no attribute 'encode'
[2025-10-15 12:46:32,725] [ERROR] [django.server] "GET /users/verify-email/ HTTP/1.1" 500 109920
[2025-10-15 12:59:01,258] [ERROR] [common] {"type": "exception", "user": "allanlondon19452122@gmail.com", "method": "POST", "path": "/users/password-reset/", "query_params": {}, "body": "<unreadable body>", "exception": "[WinError 10061] No connection could be made because the target machine actively refused it", "traceback": "Traceback (most recent call last):\n  File \"E:\\Python\\Lib\\site-packages\\django\\core\\handlers\\base.py\", line 197, in _get_response\n    response = wrapped_callback(request, *callback_args, **callback_kwargs)\n  File \"E:\\Python\\Lib\\site-packages\\django\\views\\decorators\\csrf.py\", line 65, in _view_wrapper\n    return view_func(request, *args, **kwargs)\n  File \"E:\\Python\\Lib\\site-packages\\django\\views\\generic\\base.py\", line 105, in view\n    return self.dispatch(request, *args, **kwargs)\n           ~~~~~~~~~~~~~^^^^^^^^^^^^^^^^^^^^^^^^^^\n  File \"E:\\Python\\Lib\\site-packages\\rest_framework\\views.py\", line 515, in dispatch\n    response = self.handle_exception(exc)\n  File \"E:\\Python\\Lib\\site-packages\\rest_framework\\views.py\", line 475, in handle_exception\n    self.raise_uncaught_exception(exc)\n    ~~~~~~~~~~~~~~~~~~~~~~~~~~~~~^^^^^\n  File \"E:\\Python\\Lib\\site-packages\\rest_framework\\views.py\", line 486, in raise_uncaught_exception\n    raise exc\n  File \"E:\\Python\\Lib\\site-packages\\rest_framework\\views.py\", line 512, in dispatch\n    response = handler(request, *args, **kwargs)\n  File \"E:\\2VAKIL\\AloVakil\\users\\views.py\", line 159, in post\n    send_mail(\n    ~~~~~~~~~^\n        \"Password Reset Request\",\n        ^^^^^^^^^^^^^^^^^^^^^^^^^\n    ...<3 lines>...\n        fail_silently=False,\n        ^^^^^^^^^^^^^^^^^^^^\n    )\n    ^\n  File \"E:\\Python\\Lib\\site-packages\\django\\core\\mail\\__init__.py\", line 92, in send_mail\n    return mail.send()\n           ~~~~~~~~~^^\n  File \"E:\\Python\\Lib\\site-packages\\django\\core\\mail\\message.py\", line 307, in send\n    return self.get_connection(fail_silently).send_messages([self])\n           ~~~~~~~~~~~~~~~~~~~~~~~~~~~~~~~~~~~~~~~~~~~~~~~~^^^^^^^^\n  File \"E:\\Python\\Lib\\site-packages\\django\\core\\mail\\backends\\smtp.py\", line 128, in send_messages\n    new_conn_created = self.open()\n  File \"E:\\Python\\Lib\\site-packages\\django\\core\\mail\\backends\\smtp.py\", line 86, in open\n    self.connection = self.connection_class(\n                      ~~~~~~~~~~~~~~~~~~~~~^\n        self.host, self.port, **connection_params\n        ^^^^^^^^^^^^^^^^^^^^^^^^^^^^^^^^^^^^^^^^^\n    )\n    ^\n  File \"E:\\Python\\Lib\\smtplib.py\", line 255, in __init__\n    (code, msg) = self.connect(host, port)\n                  ~~~~~~~~~~~~^^^^^^^^^^^^\n  File \"E:\\Python\\Lib\\smtplib.py\", line 341, in connect\n    self.sock = self._get_socket(host, port, self.timeout)\n                ~~~~~~~~~~~~~~~~^^^^^^^^^^^^^^^^^^^^^^^^^^\n  File \"E:\\Python\\Lib\\smtplib.py\", line 312, in _get_socket\n    return socket.create_connection((host, port), timeout,\n           ~~~~~~~~~~~~~~~~~~~~~~~~^^^^^^^^^^^^^^^^^^^^^^^\n                                    self.source_address)\n                                    ^^^^^^^^^^^^^^^^^^^^\n  File \"E:\\Python\\Lib\\socket.py\", line 864, in create_connection\n    raise exceptions[0]\n  File \"E:\\Python\\Lib\\socket.py\", line 849, in create_connection\n    sock.connect(sa)\n    ~~~~~~~~~~~~^^^^\nConnectionRefusedError: [WinError 10061] No connection could be made because the target machine actively refused it\n"}
[2025-10-15 12:59:01,277] [ERROR] [django.request] Internal Server Error: /users/password-reset/
Traceback (most recent call last):
  File "E:\Python\Lib\site-packages\django\core\handlers\exception.py", line 55, in inner
    response = get_response(request)
  File "E:\Python\Lib\site-packages\django\core\handlers\base.py", line 197, in _get_response
    response = wrapped_callback(request, *callback_args, **callback_kwargs)
  File "E:\Python\Lib\site-packages\django\views\decorators\csrf.py", line 65, in _view_wrapper
    return view_func(request, *args, **kwargs)
  File "E:\Python\Lib\site-packages\django\views\generic\base.py", line 105, in view
    return self.dispatch(request, *args, **kwargs)
           ~~~~~~~~~~~~~^^^^^^^^^^^^^^^^^^^^^^^^^^
  File "E:\Python\Lib\site-packages\rest_framework\views.py", line 515, in dispatch
    response = self.handle_exception(exc)
  File "E:\Python\Lib\site-packages\rest_framework\views.py", line 475, in handle_exception
    self.raise_uncaught_exception(exc)
    ~~~~~~~~~~~~~~~~~~~~~~~~~~~~~^^^^^
  File "E:\Python\Lib\site-packages\rest_framework\views.py", line 486, in raise_uncaught_exception
    raise exc
  File "E:\Python\Lib\site-packages\rest_framework\views.py", line 512, in dispatch
    response = handler(request, *args, **kwargs)
  File "E:\2VAKIL\AloVakil\users\views.py", line 159, in post
    send_mail(
    ~~~~~~~~~^
        "Password Reset Request",
        ^^^^^^^^^^^^^^^^^^^^^^^^^
    ...<3 lines>...
        fail_silently=False,
        ^^^^^^^^^^^^^^^^^^^^
    )
    ^
  File "E:\Python\Lib\site-packages\django\core\mail\__init__.py", line 92, in send_mail
    return mail.send()
           ~~~~~~~~~^^
  File "E:\Python\Lib\site-packages\django\core\mail\message.py", line 307, in send
    return self.get_connection(fail_silently).send_messages([self])
           ~~~~~~~~~~~~~~~~~~~~~~~~~~~~~~~~~~~~~~~~~~~~~~~~^^^^^^^^
  File "E:\Python\Lib\site-packages\django\core\mail\backends\smtp.py", line 128, in send_messages
    new_conn_created = self.open()
  File "E:\Python\Lib\site-packages\django\core\mail\backends\smtp.py", line 86, in open
    self.connection = self.connection_class(
                      ~~~~~~~~~~~~~~~~~~~~~^
        self.host, self.port, **connection_params
        ^^^^^^^^^^^^^^^^^^^^^^^^^^^^^^^^^^^^^^^^^
    )
    ^
  File "E:\Python\Lib\smtplib.py", line 255, in __init__
    (code, msg) = self.connect(host, port)
                  ~~~~~~~~~~~~^^^^^^^^^^^^
  File "E:\Python\Lib\smtplib.py", line 341, in connect
    self.sock = self._get_socket(host, port, self.timeout)
                ~~~~~~~~~~~~~~~~^^^^^^^^^^^^^^^^^^^^^^^^^^
  File "E:\Python\Lib\smtplib.py", line 312, in _get_socket
    return socket.create_connection((host, port), timeout,
           ~~~~~~~~~~~~~~~~~~~~~~~~^^^^^^^^^^^^^^^^^^^^^^^
                                    self.source_address)
                                    ^^^^^^^^^^^^^^^^^^^^
  File "E:\Python\Lib\socket.py", line 864, in create_connection
    raise exceptions[0]
  File "E:\Python\Lib\socket.py", line 849, in create_connection
    sock.connect(sa)
    ~~~~~~~~~~~~^^^^
ConnectionRefusedError: [WinError 10061] No connection could be made because the target machine actively refused it
[2025-10-15 12:59:01,280] [ERROR] [django.server] "POST /users/password-reset/ HTTP/1.1" 500 150884
[2025-10-15 13:08:01,113] [ERROR] [common] {"type": "exception", "user": "allanlondon19452122@gmail.com", "method": "GET", "path": "/users/verify-email/", "query_params": {}, "body": {}, "exception": "'NoneType' object has no attribute 'encode'", "traceback": "Traceback (most recent call last):\n  File \"E:\\Python\\Lib\\site-packages\\django\\core\\handlers\\base.py\", line 197, in _get_response\n    response = wrapped_callback(request, *callback_args, **callback_kwargs)\n  File \"E:\\Python\\Lib\\site-packages\\django\\views\\decorators\\csrf.py\", line 65, in _view_wrapper\n    return view_func(request, *args, **kwargs)\n  File \"E:\\Python\\Lib\\site-packages\\django\\views\\generic\\base.py\", line 105, in view\n    return self.dispatch(request, *args, **kwargs)\n           ~~~~~~~~~~~~~^^^^^^^^^^^^^^^^^^^^^^^^^^\n  File \"E:\\Python\\Lib\\site-packages\\rest_framework\\views.py\", line 515, in dispatch\n    response = self.handle_exception(exc)\n  File \"E:\\Python\\Lib\\site-packages\\rest_framework\\views.py\", line 475, in handle_exception\n    self.raise_uncaught_exception(exc)\n    ~~~~~~~~~~~~~~~~~~~~~~~~~~~~~^^^^^\n  File \"E:\\Python\\Lib\\site-packages\\rest_framework\\views.py\", line 486, in raise_uncaught_exception\n    raise exc\n  File \"E:\\Python\\Lib\\site-packages\\rest_framework\\views.py\", line 512, in dispatch\n    response = handler(request, *args, **kwargs)\n  File \"E:\\2VAKIL\\AloVakil\\users\\views.py\", line 49, in get\n    uid = force_str(urlsafe_base64_decode(uidb64))\n                    ~~~~~~~~~~~~~~~~~~~~~^^^^^^^^\n  File \"E:\\Python\\Lib\\site-packages\\django\\utils\\http.py\", line 191, in urlsafe_base64_decode\n    s = s.encode()\n        ^^^^^^^^\nAttributeError: 'NoneType' object has no attribute 'encode'\n"}
[2025-10-15 13:08:01,128] [ERROR] [django.request] Internal Server Error: /users/verify-email/
Traceback (most recent call last):
  File "E:\Python\Lib\site-packages\django\core\handlers\exception.py", line 55, in inner
    response = get_response(request)
  File "E:\Python\Lib\site-packages\django\core\handlers\base.py", line 197, in _get_response
    response = wrapped_callback(request, *callback_args, **callback_kwargs)
  File "E:\Python\Lib\site-packages\django\views\decorators\csrf.py", line 65, in _view_wrapper
    return view_func(request, *args, **kwargs)
  File "E:\Python\Lib\site-packages\django\views\generic\base.py", line 105, in view
    return self.dispatch(request, *args, **kwargs)
           ~~~~~~~~~~~~~^^^^^^^^^^^^^^^^^^^^^^^^^^
  File "E:\Python\Lib\site-packages\rest_framework\views.py", line 515, in dispatch
    response = self.handle_exception(exc)
  File "E:\Python\Lib\site-packages\rest_framework\views.py", line 475, in handle_exception
    self.raise_uncaught_exception(exc)
    ~~~~~~~~~~~~~~~~~~~~~~~~~~~~~^^^^^
  File "E:\Python\Lib\site-packages\rest_framework\views.py", line 486, in raise_uncaught_exception
    raise exc
  File "E:\Python\Lib\site-packages\rest_framework\views.py", line 512, in dispatch
    response = handler(request, *args, **kwargs)
  File "E:\2VAKIL\AloVakil\users\views.py", line 49, in get
    uid = force_str(urlsafe_base64_decode(uidb64))
                    ~~~~~~~~~~~~~~~~~~~~~^^^^^^^^
  File "E:\Python\Lib\site-packages\django\utils\http.py", line 191, in urlsafe_base64_decode
    s = s.encode()
        ^^^^^^^^
AttributeError: 'NoneType' object has no attribute 'encode'
[2025-10-15 13:08:01,130] [ERROR] [django.server] "GET /users/verify-email/ HTTP/1.1" 500 109920
[2025-10-16 00:27:20,523] [ERROR] [common] {"type": "exception", "user": "Anonymous", "method": "POST", "path": "/users/signup/", "query_params": {}, "body": "<unreadable body>", "exception": "ConnectionError(<urllib3.connection.HTTPConnection object at 0x0000022E2931B770>: Failed to establish a new connection: [WinError 10061] No connection could be made because the target machine actively refused it) caused by: NewConnectionError(<urllib3.connection.HTTPConnection object at 0x0000022E2931B770>: Failed to establish a new connection: [WinError 10061] No connection could be made because the target machine actively refused it)", "traceback": "Traceback (most recent call last):\n  File \"E:\\Python\\Lib\\site-packages\\urllib3\\connection.py\", line 174, in _new_conn\n    conn = connection.create_connection(\n        (self._dns_host, self.port), self.timeout, **extra_kw\n    )\n  File \"E:\\Python\\Lib\\site-packages\\urllib3\\util\\connection.py\", line 95, in create_connection\n    raise err\n  File \"E:\\Python\\Lib\\site-packages\\urllib3\\util\\connection.py\", line 85, in create_connection\n    sock.connect(sa)\n    ~~~~~~~~~~~~^^^^\nConnectionRefusedError: [WinError 10061] No connection could be made because the target machine actively refused it\n\nDuring handling of the above exception, another exception occurred:\n\nTraceback (most recent call last):\n  File \"E:\\Python\\Lib\\site-packages\\elasticsearch\\connection\\http_urllib3.py\", line 255, in perform_request\n    response = self.pool.urlopen(\n        method, url, body, retries=Retry(False), headers=request_headers, **kw\n    )\n  File \"E:\\Python\\Lib\\site-packages\\urllib3\\connectionpool.py\", line 802, in urlopen\n    retries = retries.increment(\n        method, url, error=e, _pool=self, _stacktrace=sys.exc_info()[2]\n    )\n  File \"E:\\Python\\Lib\\site-packages\\urllib3\\util\\retry.py\", line 527, in increment\n    raise six.reraise(type(error), error, _stacktrace)\n          ~~~~~~~~~~~^^^^^^^^^^^^^^^^^^^^^^^^^^^^^^^^^\n  File \"E:\\Python\\Lib\\site-packages\\urllib3\\packages\\six.py\", line 770, in reraise\n    raise value\n  File \"E:\\Python\\Lib\\site-packages\\urllib3\\connectionpool.py\", line 716, in urlopen\n    httplib_response = self._make_request(\n        conn,\n    ...<5 lines>...\n        chunked=chunked,\n    )\n  File \"E:\\Python\\Lib\\site-packages\\urllib3\\connectionpool.py\", line 416, in _make_request\n    conn.request(method, url, **httplib_request_kw)\n    ~~~~~~~~~~~~^^^^^^^^^^^^^^^^^^^^^^^^^^^^^^^^^^^\n  File \"E:\\Python\\Lib\\site-packages\\urllib3\\connection.py\", line 244, in request\n    super(HTTPConnection, self).request(method, url, body=body, headers=headers)\n    ~~~~~~~~~~~~~~~~~~~~~~~~~~~~~~~~~~~^^^^^^^^^^^^^^^^^^^^^^^^^^^^^^^^^^^^^^^^^\n  File \"E:\\Python\\Lib\\http\\client.py\", line 1338, in request\n    self._send_request(method, url, body, headers, encode_chunked)\n    ~~~~~~~~~~~~~~~~~~^^^^^^^^^^^^^^^^^^^^^^^^^^^^^^^^^^^^^^^^^^^^\n  File \"E:\\Python\\Lib\\http\\client.py\", line 1384, in _send_request\n    self.endheaders(body, encode_chunked=encode_chunked)\n    ~~~~~~~~~~~~~~~^^^^^^^^^^^^^^^^^^^^^^^^^^^^^^^^^^^^^\n  File \"E:\\Python\\Lib\\http\\client.py\", line 1333, in endheaders\n    self._send_output(message_body, encode_chunked=encode_chunked)\n    ~~~~~~~~~~~~~~~~~^^^^^^^^^^^^^^^^^^^^^^^^^^^^^^^^^^^^^^^^^^^^^\n  File \"E:\\Python\\Lib\\http\\client.py\", line 1093, in _send_output\n    self.send(msg)\n    ~~~~~~~~~^^^^^\n  File \"E:\\Python\\Lib\\http\\client.py\", line 1037, in send\n    self.connect()\n    ~~~~~~~~~~~~^^\n  File \"E:\\Python\\Lib\\site-packages\\urllib3\\connection.py\", line 205, in connect\n    conn = self._new_conn()\n  File \"E:\\Python\\Lib\\site-packages\\urllib3\\connection.py\", line 186, in _new_conn\n    raise NewConnectionError(\n        self, \"Failed to establish a new connection: %s\" % e\n    )\nurllib3.exceptions.NewConnectionError: <urllib3.connection.HTTPConnection object at 0x0000022E2931B770>: Failed to establish a new connection: [WinError 10061] No connection could be made because the target machine actively refused it\n\nDuring handling of the above exception, another exception occurred:\n\nTraceback (most recent call last):\n  File \"E:\\Python\\Lib\\site-packages\\django\\core\\handlers\\base.py\", line 197, in _get_response\n    response = wrapped_callback(request, *callback_args, **callback_kwargs)\n  File \"E:\\Python\\Lib\\site-packages\\django\\views\\decorators\\csrf.py\", line 65, in _view_wrapper\n    return view_func(request, *args, **kwargs)\n  File \"E:\\Python\\Lib\\site-packages\\django\\views\\generic\\base.py\", line 105, in view\n    return self.dispatch(request, *args, **kwargs)\n           ~~~~~~~~~~~~~^^^^^^^^^^^^^^^^^^^^^^^^^^\n  File \"E:\\Python\\Lib\\site-packages\\rest_framework\\views.py\", line 515, in dispatch\n    response = self.handle_exception(exc)\n  File \"E:\\Python\\Lib\\site-packages\\rest_framework\\views.py\", line 475, in handle_exception\n    self.raise_uncaught_exception(exc)\n    ~~~~~~~~~~~~~~~~~~~~~~~~~~~~~^^^^^\n  File \"E:\\Python\\Lib\\site-packages\\rest_framework\\views.py\", line 486, in raise_uncaught_exception\n    raise exc\n  File \"E:\\Python\\Lib\\site-packages\\rest_framework\\views.py\", line 512, in dispatch\n    response = handler(request, *args, **kwargs)\n  File \"E:\\Python\\Lib\\site-packages\\rest_framework\\generics.py\", line 194, in post\n    return self.create(request, *args, **kwargs)\n           ~~~~~~~~~~~^^^^^^^^^^^^^^^^^^^^^^^^^^\n  File \"E:\\Python\\Lib\\site-packages\\rest_framework\\mixins.py\", line 19, in create\n    self.perform_create(serializer)\n    ~~~~~~~~~~~~~~~~~~~^^^^^^^^^^^^\n  File \"E:\\2VAKIL\\AloVakil\\users\\views.py\", line 23, in perform_create\n    user = serializer.save()\n  File \"E:\\Python\\Lib\\site-packages\\rest_framework\\serializers.py\", line 210, in save\n    self.instance = self.create(validated_data)\n                    ~~~~~~~~~~~^^^^^^^^^^^^^^^^\n  File \"E:\\2VAKIL\\AloVakil\\users\\serializers.py\", line 18, in create\n    user = User.objects.create_user(\n        phone_number=validated_data['phone_number'],\n    ...<3 lines>...\n        is_active=False  # \u062a\u0627 \u062a\u0627\u06cc\u06cc\u062f OTP \u0641\u0639\u0627\u0644 \u0646\u0634\u0648\u062f\n    )\n  File \"E:\\2VAKIL\\AloVakil\\users\\models.py\", line 16, in create_user\n    user.save(using=self._db)\n    ~~~~~~~~~^^^^^^^^^^^^^^^^\n  File \"E:\\Python\\Lib\\site-packages\\django\\contrib\\auth\\base_user.py\", line 65, in save\n    super().save(*args, **kwargs)\n    ~~~~~~~~~~~~^^^^^^^^^^^^^^^^^\n  File \"E:\\Python\\Lib\\site-packages\\django\\db\\models\\base.py\", line 902, in save\n    self.save_base(\n    ~~~~~~~~~~~~~~^\n        using=using,\n        ^^^^^^^^^^^^\n    ...<2 lines>...\n        update_fields=update_fields,\n        ^^^^^^^^^^^^^^^^^^^^^^^^^^^^\n    )\n    ^\n  File \"E:\\Python\\Lib\\site-packages\\django\\db\\models\\base.py\", line 1023, in save_base\n    post_save.send(\n    ~~~~~~~~~~~~~~^\n        sender=origin,\n        ^^^^^^^^^^^^^^\n    ...<4 lines>...\n        using=using,\n        ^^^^^^^^^^^^\n    )\n    ^\n  File \"E:\\Python\\Lib\\site-packages\\django\\dispatch\\dispatcher.py\", line 189, in send\n    response = receiver(signal=self, sender=sender, **named)\n  File \"E:\\2VAKIL\\AloVakil\\users\\signals.py\", line 17, in update_user_document\n    doc.save()\n    ~~~~~~~~^^\n  File \"E:\\2VAKIL\\AloVakil\\users\\documents.py\", line 20, in save\n    return super().save(**kwargs)\n           ~~~~~~~~~~~~^^^^^^^^^^\n  File \"E:\\Python\\Lib\\site-packages\\elasticsearch_dsl\\document.py\", line 497, in save\n    meta = es.index(index=self._get_index(index), **params)\n  File \"E:\\Python\\Lib\\site-packages\\elasticsearch\\client\\utils.py\", line 347, in _wrapped\n    return func(*args, params=params, headers=headers, **kwargs)\n  File \"E:\\Python\\Lib\\site-packages\\elasticsearch\\client\\__init__.py\", line 413, in index\n    return self.transport.perform_request(\n           ~~~~~~~~~~~~~~~~~~~~~~~~~~~~~~^\n        \"POST\" if id in SKIP_IN_PATH else \"PUT\",\n        ^^^^^^^^^^^^^^^^^^^^^^^^^^^^^^^^^^^^^^^^\n    ...<3 lines>...\n        body=body,\n        ^^^^^^^^^^\n    )\n    ^\n  File \"E:\\Python\\Lib\\site-packages\\elasticsearch\\transport.py\", line 417, in perform_request\n    self._do_verify_elasticsearch(headers=headers, timeout=timeout)\n    ~~~~~~~~~~~~~~~~~~~~~~~~~~~~~^^^^^^^^^^^^^^^^^^^^^^^^^^^^^^^^^^\n  File \"E:\\Python\\Lib\\site-packages\\elasticsearch\\transport.py\", line 606, in _do_verify_elasticsearch\n    raise error\n  File \"E:\\Python\\Lib\\site-packages\\elasticsearch\\transport.py\", line 569, in _do_verify_elasticsearch\n    _, info_headers, info_response = conn.perform_request(\n                                     ~~~~~~~~~~~~~~~~~~~~^\n        \"GET\", \"/\", headers=headers, timeout=timeout\n        ^^^^^^^^^^^^^^^^^^^^^^^^^^^^^^^^^^^^^^^^^^^^\n    )\n    ^\n  File \"E:\\Python\\Lib\\site-packages\\elasticsearch\\connection\\http_urllib3.py\", line 280, in perform_request\n    raise ConnectionError(\"N/A\", str(e), e)\nelasticsearch.exceptions.ConnectionError: ConnectionError(<urllib3.connection.HTTPConnection object at 0x0000022E2931B770>: Failed to establish a new connection: [WinError 10061] No connection could be made because the target machine actively refused it) caused by: NewConnectionError(<urllib3.connection.HTTPConnection object at 0x0000022E2931B770>: Failed to establish a new connection: [WinError 10061] No connection could be made because the target machine actively refused it)\n"}
[2025-10-16 00:27:20,713] [ERROR] [django.server] "POST /users/signup/ HTTP/1.1" 500 294045
[2025-10-16 00:51:23,791] [ERROR] [common] {"type": "exception", "user": "Anonymous", "method": "POST", "path": "/users/signup/", "query_params": {}, "body": "<unreadable body>", "exception": "ConnectionError(('Connection aborted.', RemoteDisconnected('Remote end closed connection without response'))) caused by: ProtocolError(('Connection aborted.', RemoteDisconnected('Remote end closed connection without response')))", "traceback": "Traceback (most recent call last):\n  File \"E:\\Python\\Lib\\site-packages\\urllib3\\connectionpool.py\", line 716, in urlopen\n    httplib_response = self._make_request(\n        conn,\n    ...<5 lines>...\n        chunked=chunked,\n    )\n  File \"E:\\Python\\Lib\\site-packages\\urllib3\\connectionpool.py\", line 468, in _make_request\n    six.raise_from(e, None)\n    ~~~~~~~~~~~~~~^^^^^^^^^\n  File \"<string>\", line 3, in raise_from\n  File \"E:\\Python\\Lib\\site-packages\\urllib3\\connectionpool.py\", line 463, in _make_request\n    httplib_response = conn.getresponse()\n  File \"E:\\Python\\Lib\\http\\client.py\", line 1430, in getresponse\n    response.begin()\n    ~~~~~~~~~~~~~~^^\n  File \"E:\\Python\\Lib\\http\\client.py\", line 331, in begin\n    version, status, reason = self._read_status()\n                              ~~~~~~~~~~~~~~~~~^^\n  File \"E:\\Python\\Lib\\http\\client.py\", line 300, in _read_status\n    raise RemoteDisconnected(\"Remote end closed connection without\"\n                             \" response\")\nhttp.client.RemoteDisconnected: Remote end closed connection without response\n\nDuring handling of the above exception, another exception occurred:\n\nTraceback (most recent call last):\n  File \"E:\\Python\\Lib\\site-packages\\elasticsearch\\connection\\http_urllib3.py\", line 255, in perform_request\n    response = self.pool.urlopen(\n        method, url, body, retries=Retry(False), headers=request_headers, **kw\n    )\n  File \"E:\\Python\\Lib\\site-packages\\urllib3\\connectionpool.py\", line 802, in urlopen\n    retries = retries.increment(\n        method, url, error=e, _pool=self, _stacktrace=sys.exc_info()[2]\n    )\n  File \"E:\\Python\\Lib\\site-packages\\urllib3\\util\\retry.py\", line 527, in increment\n    raise six.reraise(type(error), error, _stacktrace)\n          ~~~~~~~~~~~^^^^^^^^^^^^^^^^^^^^^^^^^^^^^^^^^\n  File \"E:\\Python\\Lib\\site-packages\\urllib3\\packages\\six.py\", line 769, in reraise\n    raise value.with_traceback(tb)\n  File \"E:\\Python\\Lib\\site-packages\\urllib3\\connectionpool.py\", line 716, in urlopen\n    httplib_response = self._make_request(\n        conn,\n    ...<5 lines>...\n        chunked=chunked,\n    )\n  File \"E:\\Python\\Lib\\site-packages\\urllib3\\connectionpool.py\", line 468, in _make_request\n    six.raise_from(e, None)\n    ~~~~~~~~~~~~~~^^^^^^^^^\n  File \"<string>\", line 3, in raise_from\n  File \"E:\\Python\\Lib\\site-packages\\urllib3\\connectionpool.py\", line 463, in _make_request\n    httplib_response = conn.getresponse()\n  File \"E:\\Python\\Lib\\http\\client.py\", line 1430, in getresponse\n    response.begin()\n    ~~~~~~~~~~~~~~^^\n  File \"E:\\Python\\Lib\\http\\client.py\", line 331, in begin\n    version, status, reason = self._read_status()\n                              ~~~~~~~~~~~~~~~~~^^\n  File \"E:\\Python\\Lib\\http\\client.py\", line 300, in _read_status\n    raise RemoteDisconnected(\"Remote end closed connection without\"\n                             \" response\")\nurllib3.exceptions.ProtocolError: ('Connection aborted.', RemoteDisconnected('Remote end closed connection without response'))\n\nDuring handling of the above exception, another exception occurred:\n\nTraceback (most recent call last):\n  File \"E:\\Python\\Lib\\site-packages\\django\\core\\handlers\\base.py\", line 197, in _get_response\n    response = wrapped_callback(request, *callback_args, **callback_kwargs)\n  File \"E:\\Python\\Lib\\site-packages\\django\\views\\decorators\\csrf.py\", line 65, in _view_wrapper\n    return view_func(request, *args, **kwargs)\n  File \"E:\\Python\\Lib\\site-packages\\django\\views\\generic\\base.py\", line 105, in view\n    return self.dispatch(request, *args, **kwargs)\n           ~~~~~~~~~~~~~^^^^^^^^^^^^^^^^^^^^^^^^^^\n  File \"E:\\Python\\Lib\\site-packages\\rest_framework\\views.py\", line 515, in dispatch\n    response = self.handle_exception(exc)\n  File \"E:\\Python\\Lib\\site-packages\\rest_framework\\views.py\", line 475, in handle_exception\n    self.raise_uncaught_exception(exc)\n    ~~~~~~~~~~~~~~~~~~~~~~~~~~~~~^^^^^\n  File \"E:\\Python\\Lib\\site-packages\\rest_framework\\views.py\", line 486, in raise_uncaught_exception\n    raise exc\n  File \"E:\\Python\\Lib\\site-packages\\rest_framework\\views.py\", line 512, in dispatch\n    response = handler(request, *args, **kwargs)\n  File \"E:\\Python\\Lib\\site-packages\\rest_framework\\generics.py\", line 194, in post\n    return self.create(request, *args, **kwargs)\n           ~~~~~~~~~~~^^^^^^^^^^^^^^^^^^^^^^^^^^\n  File \"E:\\Python\\Lib\\site-packages\\rest_framework\\mixins.py\", line 19, in create\n    self.perform_create(serializer)\n    ~~~~~~~~~~~~~~~~~~~^^^^^^^^^^^^\n  File \"E:\\2VAKIL\\AloVakil\\users\\views.py\", line 23, in perform_create\n    user = serializer.save()\n  File \"E:\\Python\\Lib\\site-packages\\rest_framework\\serializers.py\", line 210, in save\n    self.instance = self.create(validated_data)\n                    ~~~~~~~~~~~^^^^^^^^^^^^^^^^\n  File \"E:\\2VAKIL\\AloVakil\\users\\serializers.py\", line 18, in create\n    user = User.objects.create_user(\n        phone_number=validated_data['phone_number'],\n    ...<3 lines>...\n        is_active=False  # \u062a\u0627 \u062a\u0627\u06cc\u06cc\u062f OTP \u0641\u0639\u0627\u0644 \u0646\u0634\u0648\u062f\n    )\n  File \"E:\\2VAKIL\\AloVakil\\users\\models.py\", line 16, in create_user\n    user.save(using=self._db)\n    ~~~~~~~~~^^^^^^^^^^^^^^^^\n  File \"E:\\Python\\Lib\\site-packages\\django\\contrib\\auth\\base_user.py\", line 65, in save\n    super().save(*args, **kwargs)\n    ~~~~~~~~~~~~^^^^^^^^^^^^^^^^^\n  File \"E:\\Python\\Lib\\site-packages\\django\\db\\models\\base.py\", line 902, in save\n    self.save_base(\n    ~~~~~~~~~~~~~~^\n        using=using,\n        ^^^^^^^^^^^^\n    ...<2 lines>...\n        update_fields=update_fields,\n        ^^^^^^^^^^^^^^^^^^^^^^^^^^^^\n    )\n    ^\n  File \"E:\\Python\\Lib\\site-packages\\django\\db\\models\\base.py\", line 1023, in save_base\n    post_save.send(\n    ~~~~~~~~~~~~~~^\n        sender=origin,\n        ^^^^^^^^^^^^^^\n    ...<4 lines>...\n        using=using,\n        ^^^^^^^^^^^^\n    )\n    ^\n  File \"E:\\Python\\Lib\\site-packages\\django\\dispatch\\dispatcher.py\", line 189, in send\n    response = receiver(signal=self, sender=sender, **named)\n  File \"E:\\2VAKIL\\AloVakil\\users\\signals.py\", line 17, in update_user_document\n    doc.save()\n    ~~~~~~~~^^\n  File \"E:\\2VAKIL\\AloVakil\\users\\documents.py\", line 20, in save\n    return super().save(**kwargs)\n           ~~~~~~~~~~~~^^^^^^^^^^\n  File \"E:\\Python\\Lib\\site-packages\\elasticsearch_dsl\\document.py\", line 497, in save\n    meta = es.index(index=self._get_index(index), **params)\n  File \"E:\\Python\\Lib\\site-packages\\elasticsearch\\client\\utils.py\", line 347, in _wrapped\n    return func(*args, params=params, headers=headers, **kwargs)\n  File \"E:\\Python\\Lib\\site-packages\\elasticsearch\\client\\__init__.py\", line 413, in index\n    return self.transport.perform_request(\n           ~~~~~~~~~~~~~~~~~~~~~~~~~~~~~~^\n        \"POST\" if id in SKIP_IN_PATH else \"PUT\",\n        ^^^^^^^^^^^^^^^^^^^^^^^^^^^^^^^^^^^^^^^^\n    ...<3 lines>...\n        body=body,\n        ^^^^^^^^^^\n    )\n    ^\n  File \"E:\\Python\\Lib\\site-packages\\elasticsearch\\transport.py\", line 417, in perform_request\n    self._do_verify_elasticsearch(headers=headers, timeout=timeout)\n    ~~~~~~~~~~~~~~~~~~~~~~~~~~~~~^^^^^^^^^^^^^^^^^^^^^^^^^^^^^^^^^^\n  File \"E:\\Python\\Lib\\site-packages\\elasticsearch\\transport.py\", line 606, in _do_verify_elasticsearch\n    raise error\n  File \"E:\\Python\\Lib\\site-packages\\elasticsearch\\transport.py\", line 569, in _do_verify_elasticsearch\n    _, info_headers, info_response = conn.perform_request(\n                                     ~~~~~~~~~~~~~~~~~~~~^\n        \"GET\", \"/\", headers=headers, timeout=timeout\n        ^^^^^^^^^^^^^^^^^^^^^^^^^^^^^^^^^^^^^^^^^^^^\n    )\n    ^\n  File \"E:\\Python\\Lib\\site-packages\\elasticsearch\\connection\\http_urllib3.py\", line 280, in perform_request\n    raise ConnectionError(\"N/A\", str(e), e)\nelasticsearch.exceptions.ConnectionError: ConnectionError(('Connection aborted.', RemoteDisconnected('Remote end closed connection without response'))) caused by: ProtocolError(('Connection aborted.', RemoteDisconnected('Remote end closed connection without response')))\n"}
[2025-10-16 00:51:23,846] [ERROR] [django.server] "POST /users/signup/ HTTP/1.1" 500 294718
[2025-10-16 12:10:35,401] [ERROR] [common] {"type": "exception", "user": "Anonymous", "method": "POST", "path": "/users/signup/", "query_params": {}, "body": "<unreadable body>", "exception": "UserDocument() takes no arguments", "traceback": "Traceback (most recent call last):\n  File \"E:\\Python\\Lib\\site-packages\\django\\core\\handlers\\base.py\", line 197, in _get_response\n    response = wrapped_callback(request, *callback_args, **callback_kwargs)\n  File \"E:\\Python\\Lib\\site-packages\\django\\views\\decorators\\csrf.py\", line 65, in _view_wrapper\n    return view_func(request, *args, **kwargs)\n  File \"E:\\Python\\Lib\\site-packages\\django\\views\\generic\\base.py\", line 105, in view\n    return self.dispatch(request, *args, **kwargs)\n           ~~~~~~~~~~~~~^^^^^^^^^^^^^^^^^^^^^^^^^^\n  File \"E:\\Python\\Lib\\site-packages\\rest_framework\\views.py\", line 515, in dispatch\n    response = self.handle_exception(exc)\n  File \"E:\\Python\\Lib\\site-packages\\rest_framework\\views.py\", line 475, in handle_exception\n    self.raise_uncaught_exception(exc)\n    ~~~~~~~~~~~~~~~~~~~~~~~~~~~~~^^^^^\n  File \"E:\\Python\\Lib\\site-packages\\rest_framework\\views.py\", line 486, in raise_uncaught_exception\n    raise exc\n  File \"E:\\Python\\Lib\\site-packages\\rest_framework\\views.py\", line 512, in dispatch\n    response = handler(request, *args, **kwargs)\n  File \"E:\\Python\\Lib\\site-packages\\rest_framework\\generics.py\", line 194, in post\n    return self.create(request, *args, **kwargs)\n           ~~~~~~~~~~~^^^^^^^^^^^^^^^^^^^^^^^^^^\n  File \"E:\\2VAKIL\\AloVakil\\users\\views.py\", line 37, in create\n    self.perform_create(serializer)\n    ~~~~~~~~~~~~~~~~~~~^^^^^^^^^^^^\n  File \"E:\\2VAKIL\\AloVakil\\users\\views.py\", line 28, in perform_create\n    user = serializer.save(is_active=True)\n  File \"E:\\Python\\Lib\\site-packages\\rest_framework\\serializers.py\", line 210, in save\n    self.instance = self.create(validated_data)\n                    ~~~~~~~~~~~^^^^^^^^^^^^^^^^\n  File \"E:\\2VAKIL\\AloVakil\\users\\serializers.py\", line 18, in create\n    user = User.objects.create_user(\n        phone_number=validated_data['phone_number'],\n    ...<3 lines>...\n        is_active=False  # \u062a\u0627 \u062a\u0627\u06cc\u06cc\u062f OTP \u0641\u0639\u0627\u0644 \u0646\u0634\u0648\u062f\n    )\n  File \"E:\\2VAKIL\\AloVakil\\users\\models.py\", line 16, in create_user\n    user.save(using=self._db)\n    ~~~~~~~~~^^^^^^^^^^^^^^^^\n  File \"E:\\Python\\Lib\\site-packages\\django\\contrib\\auth\\base_user.py\", line 65, in save\n    super().save(*args, **kwargs)\n    ~~~~~~~~~~~~^^^^^^^^^^^^^^^^^\n  File \"E:\\Python\\Lib\\site-packages\\django\\db\\models\\base.py\", line 902, in save\n    self.save_base(\n    ~~~~~~~~~~~~~~^\n        using=using,\n        ^^^^^^^^^^^^\n    ...<2 lines>...\n        update_fields=update_fields,\n        ^^^^^^^^^^^^^^^^^^^^^^^^^^^^\n    )\n    ^\n  File \"E:\\Python\\Lib\\site-packages\\django\\db\\models\\base.py\", line 1023, in save_base\n    post_save.send(\n    ~~~~~~~~~~~~~~^\n        sender=origin,\n        ^^^^^^^^^^^^^^\n    ...<4 lines>...\n        using=using,\n        ^^^^^^^^^^^^\n    )\n    ^\n  File \"E:\\Python\\Lib\\site-packages\\django\\dispatch\\dispatcher.py\", line 189, in send\n    response = receiver(signal=self, sender=sender, **named)\n  File \"E:\\2VAKIL\\AloVakil\\users\\signals.py\", line 10, in update_user_document\n    doc = UserDocument(\n        meta={'id': instance.id},\n    ...<3 lines>...\n        full_name=f\"{instance.first_name or ''} {instance.last_name or ''}\"\n    )\nTypeError: UserDocument() takes no arguments\n"}
[2025-10-16 12:10:35,555] [ERROR] [django.server] "POST /users/signup/ HTTP/1.1" 500 156045
[2025-10-16 13:15:11,386] [ERROR] [common] {"type": "exception", "user": "Anonymous", "method": "POST", "path": "/users/forgot-password/", "query_params": {}, "body": "<unreadable body>", "exception": "name 'PasswordResetCode' is not defined", "traceback": "Traceback (most recent call last):\n  File \"E:\\Python\\Lib\\site-packages\\django\\core\\handlers\\base.py\", line 197, in _get_response\n    response = wrapped_callback(request, *callback_args, **callback_kwargs)\n  File \"E:\\Python\\Lib\\site-packages\\django\\views\\decorators\\csrf.py\", line 65, in _view_wrapper\n    return view_func(request, *args, **kwargs)\n  File \"E:\\Python\\Lib\\site-packages\\django\\views\\generic\\base.py\", line 105, in view\n    return self.dispatch(request, *args, **kwargs)\n           ~~~~~~~~~~~~~^^^^^^^^^^^^^^^^^^^^^^^^^^\n  File \"E:\\Python\\Lib\\site-packages\\rest_framework\\views.py\", line 515, in dispatch\n    response = self.handle_exception(exc)\n  File \"E:\\Python\\Lib\\site-packages\\rest_framework\\views.py\", line 475, in handle_exception\n    self.raise_uncaught_exception(exc)\n    ~~~~~~~~~~~~~~~~~~~~~~~~~~~~~^^^^^\n  File \"E:\\Python\\Lib\\site-packages\\rest_framework\\views.py\", line 486, in raise_uncaught_exception\n    raise exc\n  File \"E:\\Python\\Lib\\site-packages\\rest_framework\\views.py\", line 512, in dispatch\n    response = handler(request, *args, **kwargs)\n  File \"E:\\2VAKIL\\AloVakil\\users\\views.py\", line 149, in post\n    code = PasswordResetCode.generate_code()\n           ^^^^^^^^^^^^^^^^^\nNameError: name 'PasswordResetCode' is not defined\n"}
[2025-10-16 13:15:11,426] [ERROR] [django.request] Internal Server Error: /users/forgot-password/
Traceback (most recent call last):
  File "E:\Python\Lib\site-packages\django\core\handlers\exception.py", line 55, in inner
    response = get_response(request)
  File "E:\Python\Lib\site-packages\django\core\handlers\base.py", line 197, in _get_response
    response = wrapped_callback(request, *callback_args, **callback_kwargs)
  File "E:\Python\Lib\site-packages\django\views\decorators\csrf.py", line 65, in _view_wrapper
    return view_func(request, *args, **kwargs)
  File "E:\Python\Lib\site-packages\django\views\generic\base.py", line 105, in view
    return self.dispatch(request, *args, **kwargs)
           ~~~~~~~~~~~~~^^^^^^^^^^^^^^^^^^^^^^^^^^
  File "E:\Python\Lib\site-packages\rest_framework\views.py", line 515, in dispatch
    response = self.handle_exception(exc)
  File "E:\Python\Lib\site-packages\rest_framework\views.py", line 475, in handle_exception
    self.raise_uncaught_exception(exc)
    ~~~~~~~~~~~~~~~~~~~~~~~~~~~~~^^^^^
  File "E:\Python\Lib\site-packages\rest_framework\views.py", line 486, in raise_uncaught_exception
    raise exc
  File "E:\Python\Lib\site-packages\rest_framework\views.py", line 512, in dispatch
    response = handler(request, *args, **kwargs)
  File "E:\2VAKIL\AloVakil\users\views.py", line 149, in post
    code = PasswordResetCode.generate_code()
           ^^^^^^^^^^^^^^^^^
NameError: name 'PasswordResetCode' is not defined
[2025-10-16 13:15:11,428] [ERROR] [django.server] "POST /users/forgot-password/ HTTP/1.1" 500 107144
[2025-10-16 13:59:04,411] [ERROR] [common] {"type": "exception", "user": "Anonymous", "method": "POST", "path": "/users/forgot-password/", "query_params": {}, "body": "<unreadable body>", "exception": "PasswordResetCode.generate_code() missing 1 required positional argument: 'phone_number'", "traceback": "Traceback (most recent call last):\n  File \"E:\\Python\\Lib\\site-packages\\django\\core\\handlers\\base.py\", line 197, in _get_response\n    response = wrapped_callback(request, *callback_args, **callback_kwargs)\n  File \"E:\\Python\\Lib\\site-packages\\django\\views\\decorators\\csrf.py\", line 65, in _view_wrapper\n    return view_func(request, *args, **kwargs)\n  File \"E:\\Python\\Lib\\site-packages\\django\\views\\generic\\base.py\", line 105, in view\n    return self.dispatch(request, *args, **kwargs)\n           ~~~~~~~~~~~~~^^^^^^^^^^^^^^^^^^^^^^^^^^\n  File \"E:\\Python\\Lib\\site-packages\\rest_framework\\views.py\", line 515, in dispatch\n    response = self.handle_exception(exc)\n  File \"E:\\Python\\Lib\\site-packages\\rest_framework\\views.py\", line 475, in handle_exception\n    self.raise_uncaught_exception(exc)\n    ~~~~~~~~~~~~~~~~~~~~~~~~~~~~~^^^^^\n  File \"E:\\Python\\Lib\\site-packages\\rest_framework\\views.py\", line 486, in raise_uncaught_exception\n    raise exc\n  File \"E:\\Python\\Lib\\site-packages\\rest_framework\\views.py\", line 512, in dispatch\n    response = handler(request, *args, **kwargs)\n  File \"E:\\2VAKIL\\AloVakil\\users\\views.py\", line 151, in post\n    code = PasswordResetCode.generate_code()\nTypeError: PasswordResetCode.generate_code() missing 1 required positional argument: 'phone_number'\n"}
[2025-10-16 13:59:04,428] [ERROR] [django.request] Internal Server Error: /users/forgot-password/
Traceback (most recent call last):
  File "E:\Python\Lib\site-packages\django\core\handlers\exception.py", line 55, in inner
    response = get_response(request)
  File "E:\Python\Lib\site-packages\django\core\handlers\base.py", line 197, in _get_response
    response = wrapped_callback(request, *callback_args, **callback_kwargs)
  File "E:\Python\Lib\site-packages\django\views\decorators\csrf.py", line 65, in _view_wrapper
    return view_func(request, *args, **kwargs)
  File "E:\Python\Lib\site-packages\django\views\generic\base.py", line 105, in view
    return self.dispatch(request, *args, **kwargs)
           ~~~~~~~~~~~~~^^^^^^^^^^^^^^^^^^^^^^^^^^
  File "E:\Python\Lib\site-packages\rest_framework\views.py", line 515, in dispatch
    response = self.handle_exception(exc)
  File "E:\Python\Lib\site-packages\rest_framework\views.py", line 475, in handle_exception
    self.raise_uncaught_exception(exc)
    ~~~~~~~~~~~~~~~~~~~~~~~~~~~~~^^^^^
  File "E:\Python\Lib\site-packages\rest_framework\views.py", line 486, in raise_uncaught_exception
    raise exc
  File "E:\Python\Lib\site-packages\rest_framework\views.py", line 512, in dispatch
    response = handler(request, *args, **kwargs)
  File "E:\2VAKIL\AloVakil\users\views.py", line 151, in post
    code = PasswordResetCode.generate_code()
TypeError: PasswordResetCode.generate_code() missing 1 required positional argument: 'phone_number'
[2025-10-16 13:59:04,430] [ERROR] [django.server] "POST /users/forgot-password/ HTTP/1.1" 500 107767
[2025-10-16 14:02:51,094] [ERROR] [common] {"type": "exception", "user": "Anonymous", "method": "POST", "path": "/users/forgot-password/", "query_params": {}, "body": "<unreadable body>", "exception": "PasswordResetCode.generate_code() missing 1 required positional argument: 'phone_number'", "traceback": "Traceback (most recent call last):\n  File \"E:\\Python\\Lib\\site-packages\\django\\core\\handlers\\base.py\", line 197, in _get_response\n    response = wrapped_callback(request, *callback_args, **callback_kwargs)\n  File \"E:\\Python\\Lib\\site-packages\\django\\views\\decorators\\csrf.py\", line 65, in _view_wrapper\n    return view_func(request, *args, **kwargs)\n  File \"E:\\Python\\Lib\\site-packages\\django\\views\\generic\\base.py\", line 105, in view\n    return self.dispatch(request, *args, **kwargs)\n           ~~~~~~~~~~~~~^^^^^^^^^^^^^^^^^^^^^^^^^^\n  File \"E:\\Python\\Lib\\site-packages\\rest_framework\\views.py\", line 515, in dispatch\n    response = self.handle_exception(exc)\n  File \"E:\\Python\\Lib\\site-packages\\rest_framework\\views.py\", line 475, in handle_exception\n    self.raise_uncaught_exception(exc)\n    ~~~~~~~~~~~~~~~~~~~~~~~~~~~~~^^^^^\n  File \"E:\\Python\\Lib\\site-packages\\rest_framework\\views.py\", line 486, in raise_uncaught_exception\n    raise exc\n  File \"E:\\Python\\Lib\\site-packages\\rest_framework\\views.py\", line 512, in dispatch\n    response = handler(request, *args, **kwargs)\n  File \"E:\\2VAKIL\\AloVakil\\users\\views.py\", line 151, in post\n    code = PasswordResetCode.generate_code()\nTypeError: PasswordResetCode.generate_code() missing 1 required positional argument: 'phone_number'\n"}
[2025-10-16 14:02:51,113] [ERROR] [django.request] Internal Server Error: /users/forgot-password/
Traceback (most recent call last):
  File "E:\Python\Lib\site-packages\django\core\handlers\exception.py", line 55, in inner
    response = get_response(request)
  File "E:\Python\Lib\site-packages\django\core\handlers\base.py", line 197, in _get_response
    response = wrapped_callback(request, *callback_args, **callback_kwargs)
  File "E:\Python\Lib\site-packages\django\views\decorators\csrf.py", line 65, in _view_wrapper
    return view_func(request, *args, **kwargs)
  File "E:\Python\Lib\site-packages\django\views\generic\base.py", line 105, in view
    return self.dispatch(request, *args, **kwargs)
           ~~~~~~~~~~~~~^^^^^^^^^^^^^^^^^^^^^^^^^^
  File "E:\Python\Lib\site-packages\rest_framework\views.py", line 515, in dispatch
    response = self.handle_exception(exc)
  File "E:\Python\Lib\site-packages\rest_framework\views.py", line 475, in handle_exception
    self.raise_uncaught_exception(exc)
    ~~~~~~~~~~~~~~~~~~~~~~~~~~~~~^^^^^
  File "E:\Python\Lib\site-packages\rest_framework\views.py", line 486, in raise_uncaught_exception
    raise exc
  File "E:\Python\Lib\site-packages\rest_framework\views.py", line 512, in dispatch
    response = handler(request, *args, **kwargs)
  File "E:\2VAKIL\AloVakil\users\views.py", line 151, in post
    code = PasswordResetCode.generate_code()
TypeError: PasswordResetCode.generate_code() missing 1 required positional argument: 'phone_number'
[2025-10-16 14:02:51,114] [ERROR] [django.server] "POST /users/forgot-password/ HTTP/1.1" 500 107767
[2025-10-16 20:30:08,460] [ERROR] [common] {"type": "exception", "user": "Anonymous", "method": "GET", "path": "/users/signup/", "query_params": {}, "body": {}, "exception": "Field name `email` is not valid for model `User` in `users.serializers.UserSerializer`.", "traceback": "Traceback (most recent call last):\n  File \"E:\\Python\\Lib\\site-packages\\django\\core\\handlers\\base.py\", line 220, in _get_response\n    response = response.render()\n  File \"E:\\Python\\Lib\\site-packages\\django\\template\\response.py\", line 114, in render\n    self.content = self.rendered_content\n                   ^^^^^^^^^^^^^^^^^^^^^\n  File \"E:\\Python\\Lib\\site-packages\\rest_framework\\response.py\", line 74, in rendered_content\n    ret = renderer.render(self.data, accepted_media_type, context)\n  File \"E:\\Python\\Lib\\site-packages\\rest_framework\\renderers.py\", line 731, in render\n    context = self.get_context(data, accepted_media_type, renderer_context)\n  File \"E:\\Python\\Lib\\site-packages\\rest_framework\\renderers.py\", line 662, in get_context\n    raw_data_post_form = self.get_raw_data_form(data, view, 'POST', request)\n  File \"E:\\Python\\Lib\\site-packages\\rest_framework\\renderers.py\", line 569, in get_raw_data_form\n    data = serializer.data.copy()\n           ^^^^^^^^^^^^^^^\n  File \"E:\\Python\\Lib\\site-packages\\rest_framework\\serializers.py\", line 573, in data\n    ret = super().data\n          ^^^^^^^^^^^^\n  File \"E:\\Python\\Lib\\site-packages\\rest_framework\\serializers.py\", line 255, in data\n    self._data = self.get_initial()\n                 ~~~~~~~~~~~~~~~~^^\n  File \"E:\\Python\\Lib\\site-packages\\rest_framework\\serializers.py\", line 423, in get_initial\n    for field in self.fields.values()\n                 ^^^^^^^^^^^\n  File \"E:\\Python\\Lib\\site-packages\\django\\utils\\functional.py\", line 47, in __get__\n    res = instance.__dict__[self.name] = self.func(instance)\n                                         ~~~~~~~~~^^^^^^^^^^\n  File \"E:\\Python\\Lib\\site-packages\\rest_framework\\serializers.py\", line 374, in fields\n    for key, value in self.get_fields().items():\n                      ~~~~~~~~~~~~~~~^^\n  File \"E:\\Python\\Lib\\site-packages\\rest_framework\\serializers.py\", line 1105, in get_fields\n    field_class, field_kwargs = self.build_field(\n                                ~~~~~~~~~~~~~~~~^\n        source, info, model, depth\n        ^^^^^^^^^^^^^^^^^^^^^^^^^^\n    )\n    ^\n  File \"E:\\Python\\Lib\\site-packages\\rest_framework\\serializers.py\", line 1251, in build_field\n    return self.build_unknown_field(field_name, model_class)\n           ~~~~~~~~~~~~~~~~~~~~~~~~^^^^^^^^^^^^^^^^^^^^^^^^^\n  File \"E:\\Python\\Lib\\site-packages\\rest_framework\\serializers.py\", line 1369, in build_unknown_field\n    raise ImproperlyConfigured(\n    ...<2 lines>...\n    )\ndjango.core.exceptions.ImproperlyConfigured: Field name `email` is not valid for model `User` in `users.serializers.UserSerializer`.\n"}
[2025-10-16 20:30:08,517] [ERROR] [django.request] Internal Server Error: /users/signup/
Traceback (most recent call last):
  File "E:\Python\Lib\site-packages\django\core\handlers\exception.py", line 55, in inner
    response = get_response(request)
  File "E:\Python\Lib\site-packages\django\core\handlers\base.py", line 220, in _get_response
    response = response.render()
  File "E:\Python\Lib\site-packages\django\template\response.py", line 114, in render
    self.content = self.rendered_content
                   ^^^^^^^^^^^^^^^^^^^^^
  File "E:\Python\Lib\site-packages\rest_framework\response.py", line 74, in rendered_content
    ret = renderer.render(self.data, accepted_media_type, context)
  File "E:\Python\Lib\site-packages\rest_framework\renderers.py", line 731, in render
    context = self.get_context(data, accepted_media_type, renderer_context)
  File "E:\Python\Lib\site-packages\rest_framework\renderers.py", line 662, in get_context
    raw_data_post_form = self.get_raw_data_form(data, view, 'POST', request)
  File "E:\Python\Lib\site-packages\rest_framework\renderers.py", line 569, in get_raw_data_form
    data = serializer.data.copy()
           ^^^^^^^^^^^^^^^
  File "E:\Python\Lib\site-packages\rest_framework\serializers.py", line 573, in data
    ret = super().data
          ^^^^^^^^^^^^
  File "E:\Python\Lib\site-packages\rest_framework\serializers.py", line 255, in data
    self._data = self.get_initial()
                 ~~~~~~~~~~~~~~~~^^
  File "E:\Python\Lib\site-packages\rest_framework\serializers.py", line 423, in get_initial
    for field in self.fields.values()
                 ^^^^^^^^^^^
  File "E:\Python\Lib\site-packages\django\utils\functional.py", line 47, in __get__
    res = instance.__dict__[self.name] = self.func(instance)
                                         ~~~~~~~~~^^^^^^^^^^
  File "E:\Python\Lib\site-packages\rest_framework\serializers.py", line 374, in fields
    for key, value in self.get_fields().items():
                      ~~~~~~~~~~~~~~~^^
  File "E:\Python\Lib\site-packages\rest_framework\serializers.py", line 1105, in get_fields
    field_class, field_kwargs = self.build_field(
                                ~~~~~~~~~~~~~~~~^
        source, info, model, depth
        ^^^^^^^^^^^^^^^^^^^^^^^^^^
    )
    ^
  File "E:\Python\Lib\site-packages\rest_framework\serializers.py", line 1251, in build_field
    return self.build_unknown_field(field_name, model_class)
           ~~~~~~~~~~~~~~~~~~~~~~~~^^^^^^^^^^^^^^^^^^^^^^^^^
  File "E:\Python\Lib\site-packages\rest_framework\serializers.py", line 1369, in build_unknown_field
    raise ImproperlyConfigured(
    ...<2 lines>...
    )
django.core.exceptions.ImproperlyConfigured: Field name `email` is not valid for model `User` in `users.serializers.UserSerializer`.
[2025-10-16 20:30:08,519] [ERROR] [django.server] "GET /users/signup/ HTTP/1.1" 500 146620
[2025-10-16 20:31:02,434] [ERROR] [common] {"type": "exception", "user": "Anonymous", "method": "GET", "path": "/users/signup/", "query_params": {}, "body": {}, "exception": "Field name `email` is not valid for model `User` in `users.serializers.UserSerializer`.", "traceback": "Traceback (most recent call last):\n  File \"E:\\Python\\Lib\\site-packages\\django\\core\\handlers\\base.py\", line 220, in _get_response\n    response = response.render()\n  File \"E:\\Python\\Lib\\site-packages\\django\\template\\response.py\", line 114, in render\n    self.content = self.rendered_content\n                   ^^^^^^^^^^^^^^^^^^^^^\n  File \"E:\\Python\\Lib\\site-packages\\rest_framework\\response.py\", line 74, in rendered_content\n    ret = renderer.render(self.data, accepted_media_type, context)\n  File \"E:\\Python\\Lib\\site-packages\\rest_framework\\renderers.py\", line 731, in render\n    context = self.get_context(data, accepted_media_type, renderer_context)\n  File \"E:\\Python\\Lib\\site-packages\\rest_framework\\renderers.py\", line 662, in get_context\n    raw_data_post_form = self.get_raw_data_form(data, view, 'POST', request)\n  File \"E:\\Python\\Lib\\site-packages\\rest_framework\\renderers.py\", line 569, in get_raw_data_form\n    data = serializer.data.copy()\n           ^^^^^^^^^^^^^^^\n  File \"E:\\Python\\Lib\\site-packages\\rest_framework\\serializers.py\", line 573, in data\n    ret = super().data\n          ^^^^^^^^^^^^\n  File \"E:\\Python\\Lib\\site-packages\\rest_framework\\serializers.py\", line 255, in data\n    self._data = self.get_initial()\n                 ~~~~~~~~~~~~~~~~^^\n  File \"E:\\Python\\Lib\\site-packages\\rest_framework\\serializers.py\", line 423, in get_initial\n    for field in self.fields.values()\n                 ^^^^^^^^^^^\n  File \"E:\\Python\\Lib\\site-packages\\django\\utils\\functional.py\", line 47, in __get__\n    res = instance.__dict__[self.name] = self.func(instance)\n                                         ~~~~~~~~~^^^^^^^^^^\n  File \"E:\\Python\\Lib\\site-packages\\rest_framework\\serializers.py\", line 374, in fields\n    for key, value in self.get_fields().items():\n                      ~~~~~~~~~~~~~~~^^\n  File \"E:\\Python\\Lib\\site-packages\\rest_framework\\serializers.py\", line 1105, in get_fields\n    field_class, field_kwargs = self.build_field(\n                                ~~~~~~~~~~~~~~~~^\n        source, info, model, depth\n        ^^^^^^^^^^^^^^^^^^^^^^^^^^\n    )\n    ^\n  File \"E:\\Python\\Lib\\site-packages\\rest_framework\\serializers.py\", line 1251, in build_field\n    return self.build_unknown_field(field_name, model_class)\n           ~~~~~~~~~~~~~~~~~~~~~~~~^^^^^^^^^^^^^^^^^^^^^^^^^\n  File \"E:\\Python\\Lib\\site-packages\\rest_framework\\serializers.py\", line 1369, in build_unknown_field\n    raise ImproperlyConfigured(\n    ...<2 lines>...\n    )\ndjango.core.exceptions.ImproperlyConfigured: Field name `email` is not valid for model `User` in `users.serializers.UserSerializer`.\n"}
[2025-10-16 20:31:02,459] [ERROR] [django.request] Internal Server Error: /users/signup/
Traceback (most recent call last):
  File "E:\Python\Lib\site-packages\django\core\handlers\exception.py", line 55, in inner
    response = get_response(request)
  File "E:\Python\Lib\site-packages\django\core\handlers\base.py", line 220, in _get_response
    response = response.render()
  File "E:\Python\Lib\site-packages\django\template\response.py", line 114, in render
    self.content = self.rendered_content
                   ^^^^^^^^^^^^^^^^^^^^^
  File "E:\Python\Lib\site-packages\rest_framework\response.py", line 74, in rendered_content
    ret = renderer.render(self.data, accepted_media_type, context)
  File "E:\Python\Lib\site-packages\rest_framework\renderers.py", line 731, in render
    context = self.get_context(data, accepted_media_type, renderer_context)
  File "E:\Python\Lib\site-packages\rest_framework\renderers.py", line 662, in get_context
    raw_data_post_form = self.get_raw_data_form(data, view, 'POST', request)
  File "E:\Python\Lib\site-packages\rest_framework\renderers.py", line 569, in get_raw_data_form
    data = serializer.data.copy()
           ^^^^^^^^^^^^^^^
  File "E:\Python\Lib\site-packages\rest_framework\serializers.py", line 573, in data
    ret = super().data
          ^^^^^^^^^^^^
  File "E:\Python\Lib\site-packages\rest_framework\serializers.py", line 255, in data
    self._data = self.get_initial()
                 ~~~~~~~~~~~~~~~~^^
  File "E:\Python\Lib\site-packages\rest_framework\serializers.py", line 423, in get_initial
    for field in self.fields.values()
                 ^^^^^^^^^^^
  File "E:\Python\Lib\site-packages\django\utils\functional.py", line 47, in __get__
    res = instance.__dict__[self.name] = self.func(instance)
                                         ~~~~~~~~~^^^^^^^^^^
  File "E:\Python\Lib\site-packages\rest_framework\serializers.py", line 374, in fields
    for key, value in self.get_fields().items():
                      ~~~~~~~~~~~~~~~^^
  File "E:\Python\Lib\site-packages\rest_framework\serializers.py", line 1105, in get_fields
    field_class, field_kwargs = self.build_field(
                                ~~~~~~~~~~~~~~~~^
        source, info, model, depth
        ^^^^^^^^^^^^^^^^^^^^^^^^^^
    )
    ^
  File "E:\Python\Lib\site-packages\rest_framework\serializers.py", line 1251, in build_field
    return self.build_unknown_field(field_name, model_class)
           ~~~~~~~~~~~~~~~~~~~~~~~~^^^^^^^^^^^^^^^^^^^^^^^^^
  File "E:\Python\Lib\site-packages\rest_framework\serializers.py", line 1369, in build_unknown_field
    raise ImproperlyConfigured(
    ...<2 lines>...
    )
django.core.exceptions.ImproperlyConfigured: Field name `email` is not valid for model `User` in `users.serializers.UserSerializer`.
[2025-10-16 20:31:02,461] [ERROR] [django.server] "GET /users/signup/ HTTP/1.1" 500 146757
[2025-10-16 20:31:03,754] [ERROR] [common] {"type": "exception", "user": "Anonymous", "method": "GET", "path": "/users/signup/", "query_params": {}, "body": {}, "exception": "Field name `email` is not valid for model `User` in `users.serializers.UserSerializer`.", "traceback": "Traceback (most recent call last):\n  File \"E:\\Python\\Lib\\site-packages\\django\\core\\handlers\\base.py\", line 220, in _get_response\n    response = response.render()\n  File \"E:\\Python\\Lib\\site-packages\\django\\template\\response.py\", line 114, in render\n    self.content = self.rendered_content\n                   ^^^^^^^^^^^^^^^^^^^^^\n  File \"E:\\Python\\Lib\\site-packages\\rest_framework\\response.py\", line 74, in rendered_content\n    ret = renderer.render(self.data, accepted_media_type, context)\n  File \"E:\\Python\\Lib\\site-packages\\rest_framework\\renderers.py\", line 731, in render\n    context = self.get_context(data, accepted_media_type, renderer_context)\n  File \"E:\\Python\\Lib\\site-packages\\rest_framework\\renderers.py\", line 662, in get_context\n    raw_data_post_form = self.get_raw_data_form(data, view, 'POST', request)\n  File \"E:\\Python\\Lib\\site-packages\\rest_framework\\renderers.py\", line 569, in get_raw_data_form\n    data = serializer.data.copy()\n           ^^^^^^^^^^^^^^^\n  File \"E:\\Python\\Lib\\site-packages\\rest_framework\\serializers.py\", line 573, in data\n    ret = super().data\n          ^^^^^^^^^^^^\n  File \"E:\\Python\\Lib\\site-packages\\rest_framework\\serializers.py\", line 255, in data\n    self._data = self.get_initial()\n                 ~~~~~~~~~~~~~~~~^^\n  File \"E:\\Python\\Lib\\site-packages\\rest_framework\\serializers.py\", line 423, in get_initial\n    for field in self.fields.values()\n                 ^^^^^^^^^^^\n  File \"E:\\Python\\Lib\\site-packages\\django\\utils\\functional.py\", line 47, in __get__\n    res = instance.__dict__[self.name] = self.func(instance)\n                                         ~~~~~~~~~^^^^^^^^^^\n  File \"E:\\Python\\Lib\\site-packages\\rest_framework\\serializers.py\", line 374, in fields\n    for key, value in self.get_fields().items():\n                      ~~~~~~~~~~~~~~~^^\n  File \"E:\\Python\\Lib\\site-packages\\rest_framework\\serializers.py\", line 1105, in get_fields\n    field_class, field_kwargs = self.build_field(\n                                ~~~~~~~~~~~~~~~~^\n        source, info, model, depth\n        ^^^^^^^^^^^^^^^^^^^^^^^^^^\n    )\n    ^\n  File \"E:\\Python\\Lib\\site-packages\\rest_framework\\serializers.py\", line 1251, in build_field\n    return self.build_unknown_field(field_name, model_class)\n           ~~~~~~~~~~~~~~~~~~~~~~~~^^^^^^^^^^^^^^^^^^^^^^^^^\n  File \"E:\\Python\\Lib\\site-packages\\rest_framework\\serializers.py\", line 1369, in build_unknown_field\n    raise ImproperlyConfigured(\n    ...<2 lines>...\n    )\ndjango.core.exceptions.ImproperlyConfigured: Field name `email` is not valid for model `User` in `users.serializers.UserSerializer`.\n"}
[2025-10-16 20:31:03,773] [ERROR] [django.request] Internal Server Error: /users/signup/
Traceback (most recent call last):
  File "E:\Python\Lib\site-packages\django\core\handlers\exception.py", line 55, in inner
    response = get_response(request)
  File "E:\Python\Lib\site-packages\django\core\handlers\base.py", line 220, in _get_response
    response = response.render()
  File "E:\Python\Lib\site-packages\django\template\response.py", line 114, in render
    self.content = self.rendered_content
                   ^^^^^^^^^^^^^^^^^^^^^
  File "E:\Python\Lib\site-packages\rest_framework\response.py", line 74, in rendered_content
    ret = renderer.render(self.data, accepted_media_type, context)
  File "E:\Python\Lib\site-packages\rest_framework\renderers.py", line 731, in render
    context = self.get_context(data, accepted_media_type, renderer_context)
  File "E:\Python\Lib\site-packages\rest_framework\renderers.py", line 662, in get_context
    raw_data_post_form = self.get_raw_data_form(data, view, 'POST', request)
  File "E:\Python\Lib\site-packages\rest_framework\renderers.py", line 569, in get_raw_data_form
    data = serializer.data.copy()
           ^^^^^^^^^^^^^^^
  File "E:\Python\Lib\site-packages\rest_framework\serializers.py", line 573, in data
    ret = super().data
          ^^^^^^^^^^^^
  File "E:\Python\Lib\site-packages\rest_framework\serializers.py", line 255, in data
    self._data = self.get_initial()
                 ~~~~~~~~~~~~~~~~^^
  File "E:\Python\Lib\site-packages\rest_framework\serializers.py", line 423, in get_initial
    for field in self.fields.values()
                 ^^^^^^^^^^^
  File "E:\Python\Lib\site-packages\django\utils\functional.py", line 47, in __get__
    res = instance.__dict__[self.name] = self.func(instance)
                                         ~~~~~~~~~^^^^^^^^^^
  File "E:\Python\Lib\site-packages\rest_framework\serializers.py", line 374, in fields
    for key, value in self.get_fields().items():
                      ~~~~~~~~~~~~~~~^^
  File "E:\Python\Lib\site-packages\rest_framework\serializers.py", line 1105, in get_fields
    field_class, field_kwargs = self.build_field(
                                ~~~~~~~~~~~~~~~~^
        source, info, model, depth
        ^^^^^^^^^^^^^^^^^^^^^^^^^^
    )
    ^
  File "E:\Python\Lib\site-packages\rest_framework\serializers.py", line 1251, in build_field
    return self.build_unknown_field(field_name, model_class)
           ~~~~~~~~~~~~~~~~~~~~~~~~^^^^^^^^^^^^^^^^^^^^^^^^^
  File "E:\Python\Lib\site-packages\rest_framework\serializers.py", line 1369, in build_unknown_field
    raise ImproperlyConfigured(
    ...<2 lines>...
    )
django.core.exceptions.ImproperlyConfigured: Field name `email` is not valid for model `User` in `users.serializers.UserSerializer`.
[2025-10-16 20:31:03,775] [ERROR] [django.server] "GET /users/signup/ HTTP/1.1" 500 146757
